Workbook

Sheet Dashboard
B1: PORTFÓLIO DE INVESTIMENTOS | DASHBOARD EXECUTIVO
B2: Painel Consolidado de Posição Patrimonial, Rentabilidade e Alocação Estratégica
B4: PATRIMÔNIO TOTAL | D4: TOTAL INVESTIDO | F4: RENDIMENTO TOTAL | H4: RENTABILIDADE (%) | J4: PROVENTOS RECEBIDOS | L4: CDI ATUAL (a.a.)
B5: ='Carteira Atual'!#REF! | D5: ='Carteira Atual'!#REF! | F5: ='Carteira Atual'!#REF! | H5: ='Carteira Atual'!#REF! | J5: ='Carteira Atual'!#REF! | L5: =Indicadores!B2
B6: Posição Bruta Atualizada | D6: Custo Base de Aquisição | F6: Ganho Líquido + Proventos | H6: Retorno Global Ponderado | J6: Dividendos, JCP e Cupons | L6: Taxa Benchmark
B8: 📊 RESUMO E METAS POR CLASSE DE ATIVO
B9: Classe | C9: Total Aplicado | D9: Saldo Atual | E9: Rendimento (R$) | F9: Rentabilidade | G9: % Real | H9: % Meta
B10: Renda Fixa | C10: =SUMIF('Carteira Atual'!$D$4:$D$39, B10, 'Carteira Atual'!$I$4:$I$39) | D10: =SUMIF('Carteira Atual'!$D$4:$D$39, B10, 'Carteira Atual'!$K$4:$K$39) | E10: =SUMIF('Carteira Atual'!$D$4:$D$39, B10, 'Carteira Atual'!$M$4:$M$39) | F10: =IF(C10>0, E10/C10, 0) | G10: =IF($D$17>0, D10/$D$17, 0) | H10: 0.35
B11: Exterior | C11: =SUMIF('Carteira Atual'!$D$4:$D$39, B11, 'Carteira Atual'!$I$4:$I$39) | D11: =SUMIF('Carteira Atual'!$D$4:$D$39, B11, 'Carteira Atual'!$K$4:$K$39) | E11: =SUMIF('Carteira Atual'!$D$4:$D$39, B11, 'Carteira Atual'!$M$4:$M$39) | F11: =IF(C11>0, E11/C11, 0) | G11: =IF($D$17>0, D11/$D$17, 0) | H11: 0.25
B12: Renda Variável | C12: =SUMIF('Carteira Atual'!$D$4:$D$39, B12, 'Carteira Atual'!$I$4:$I$39) | D12: =SUMIF('Carteira Atual'!$D$4:$D$39, B12, 'Carteira Atual'!$K$4:$K$39) | E12: =SUMIF('Carteira Atual'!$D$4:$D$39, B12, 'Carteira Atual'!$M$4:$M$39) | F12: =IF(C12>0, E12/C12, 0) | G12: =IF($D$17>0, D12/$D$17, 0) | H12: 0.2
B13: Tesouro Direto | C13: =SUMIF('Carteira Atual'!$D$4:$D$39, B13, 'Carteira Atual'!$I$4:$I$39) | D13: =SUMIF('Carteira Atual'!$D$4:$D$39, B13, 'Carteira Atual'!$K$4:$K$39) | E13: =SUMIF('Carteira Atual'!$D$4:$D$39, B13, 'Carteira Atual'!$M$4:$M$39) | F13: =IF(C13>0, E13/C13, 0) | G13: =IF($D$17>0, D13/$D$17, 0) | H13: 0.1
B14: Cripto | C14: =SUMIF('Carteira Atual'!$D$4:$D$39, B14, 'Carteira Atual'!$I$4:$I$39) | D14: =SUMIF('Carteira Atual'!$D$4:$D$39, B14, 'Carteira Atual'!$K$4:$K$39) | E14: =SUMIF('Carteira Atual'!$D$4:$D$39, B14, 'Carteira Atual'!$M$4:$M$39) | F14: =IF(C14>0, E14/C14, 0) | G14: =IF($D$17>0, D14/$D$17, 0) | H14: 0.05
B15: Caixa | C15: =SUMIF('Carteira Atual'!$D$4:$D$39, B15, 'Carteira Atual'!$I$4:$I$39) | D15: =SUMIF('Carteira Atual'!$D$4:$D$39, B15, 'Carteira Atual'!$K$4:$K$39) | E15: =SUMIF('Carteira Atual'!$D$4:$D$39, B15, 'Carteira Atual'!$M$4:$M$39) | F15: =IF(C15>0, E15/C15, 0) | G15: =IF($D$17>0, D15/$D$17, 0) | H15: 0.03
B16: Moeda | C16: =SUMIF('Carteira Atual'!$D$4:$D$39, B16, 'Carteira Atual'!$I$4:$I$39) | D16: =SUMIF('Carteira Atual'!$D$4:$D$39, B16, 'Carteira Atual'!$K$4:$K$39) | E16: =SUMIF('Carteira Atual'!$D$4:$D$39, B16, 'Carteira Atual'!$M$4:$M$39) | F16: =IF(C16>0, E16/C16, 0) | G16: =IF($D$17>0, D16/$D$17, 0) | H16: 0.02
B17: TOTAL | C17: =SUM(C10:C16) | D17: =SUM(D10:D16) | E17: =SUM(E10:E16) | F17: =IF(C17>0, E17/C17, 0) | G17: =SUM(G10:G16) | H17: =SUM(H10:H16)
B19: 🏛️ POSIÇÃO POR INSTITUIÇÃO / CORRETORA
B20: Instituição | C20: Total Aplicado | D20: Saldo Atual | E20: % Carteira
B21: XP | C21: =SUMIF('Carteira Atual'!$C$4:$C$39, B21, 'Carteira Atual'!$I$4:$I$39) | D21: =SUMIF('Carteira Atual'!$C$4:$C$39, B21, 'Carteira Atual'!$K$4:$K$39) | E21: =IF($D$28>0, D21/$D$28, 0)
B22: Avenue | C22: =SUMIF('Carteira Atual'!$C$4:$C$39, B22, 'Carteira Atual'!$I$4:$I$39) | D22: =SUMIF('Carteira Atual'!$C$4:$C$39, B22, 'Carteira Atual'!$K$4:$K$39) | E22: =IF($D$28>0, D22/$D$28, 0)
B23: C6 | C23: =SUMIF('Carteira Atual'!$C$4:$C$39, B23, 'Carteira Atual'!$I$4:$I$39) | D23: =SUMIF('Carteira Atual'!$C$4:$C$39, B23, 'Carteira Atual'!$K$4:$K$39) | E23: =IF($D$28>0, D23/$D$28, 0)
B24: Clear | C24: =SUMIF('Carteira Atual'!$C$4:$C$39, B24, 'Carteira Atual'!$I$4:$I$39) | D24: =SUMIF('Carteira Atual'!$C$4:$C$39, B24, 'Carteira Atual'!$K$4:$K$39) | E24: =IF($D$28>0, D24/$D$28, 0)
B25: Binance | C25: =SUMIF('Carteira Atual'!$C$4:$C$39, B25, 'Carteira Atual'!$I$4:$I$39) | D25: =SUMIF('Carteira Atual'!$C$4:$C$39, B25, 'Carteira Atual'!$K$4:$K$39) | E25: =IF($D$28>0, D25/$D$28, 0)
B26: Wise | C26: =SUMIF('Carteira Atual'!$C$4:$C$39, B26, 'Carteira Atual'!$I$4:$I$39) | D26: =SUMIF('Carteira Atual'!$C$4:$C$39, B26, 'Carteira Atual'!$K$4:$K$39) | E26: =IF($D$28>0, D26/$D$28, 0)
B27: Mercado Pago | C27: =SUMIF('Carteira Atual'!$C$4:$C$39, B27, 'Carteira Atual'!$I$4:$I$39) | D27: =SUMIF('Carteira Atual'!$C$4:$C$39, B27, 'Carteira Atual'!$K$4:$K$39) | E27: =IF($D$28>0, D27/$D$28, 0)
B28: TOTAL | C28: =SUM(C21:C27) | D28: =SUM(D21:D27) | E28: =SUM(E21:E27)
B30: 🌎 EXPOSIÇÃO CAMBIAL (MOEDAS)
B31: Moeda | C31: Cotação (R$) | D31: Saldo em R$ | E31: % Carteira
B32: BRL (Real) | C32: 1.00 | D32: =SUMIF('Carteira Atual'!$F$4:$F$39, "BRL", 'Carteira Atual'!$K$4:$K$39) | E32: =IF($D$35>0, D32/$D$35, 0)
B33: USD (Dólar) | C33: =Indicadores!E2 | D33: =SUMIF('Carteira Atual'!$F$4:$F$39, "USD", 'Carteira Atual'!$K$4:$K$39) | E33: =IF($D$35>0, D33/$D$35, 0)
B34: GBP (Libra) | C34: =Indicadores!F2 | D34: =SUMIF('Carteira Atual'!$F$4:$F$39, "GBP", 'Carteira Atual'!$K$4:$K$39) | E34: =IF($D$35>0, D34/$D$35, 0)
B35: TOTAL | C35: - | D35: =SUM(D32:D34) | E35: =SUM(E32:E34)

Sheet Carteira Atual
A1: CARTEIRA ATUAL & TABELA DE LANÇAMENTOS DE INVESTIMENTOS
A2: 💡 Instrução: Digite o 'Valor Aplicado Original' (Col H), 'Saldo Atual Original' (Col J) e 'Proventos' (Col L). As demais colunas são calculadas 100% no automático!
A3: Código | B3: Ativo | C3: Instituição | D3: Classe | E3: Subclasse | F3: Moeda | G3: Câmbio (R$) | H3: Valor Aplicado Original | I3: Valor Aplicado (R$) | J3: Saldo Atual Original | K3: Saldo Atual (R$) | L3: Proventos (R$) | M3: Rendimento (R$) | N3: Rentabilidade (%) | O3: % da Carteira | P3: Meta (%) | Q3: Desvio vs Meta | R3: Observação / Carteira
A4: MP-CONTA | B4: =IFERROR(VLOOKUP(A4, Cadastro!$B$2:$G$38, 5, FALSE), "") | C4: =IFERROR(VLOOKUP(A4, Cadastro!$B$2:$C$38, 2, FALSE), "") | D4: =IFERROR(VLOOKUP(A4, Cadastro!$B$2:$D$38, 3, FALSE), "") | E4: =IFERROR(VLOOKUP(A4, Cadastro!$B$2:$E$38, 4, FALSE), "") | F4: =IFERROR(VLOOKUP(A4, Cadastro!$B$2:$J$38, 9, FALSE), "BRL") | G4: =IF(F4="USD", Indicadores!$E$2, IF(F4="GBP", Indicadores!$F$2, 1)) | H4: 1500 | I4: =H4*G4 | J4: 1665 | K4: =J4*G4 | L4: 0 | M4: =(K4-I4)+L4 | N4: =IF(I4>0, M4/I4, 0) | O4: =IF(#REF!>0, K4/#REF!, 0) | P4: 0.03 | Q4: =O4-P4 | R4: Carro
A5: CLR-VALE3 | B5: =IFERROR(VLOOKUP(A5, Cadastro!$B$2:$G$38, 5, FALSE), "") | C5: =IFERROR(VLOOKUP(A5, Cadastro!$B$2:$C$38, 2, FALSE), "") | D5: =IFERROR(VLOOKUP(A5, Cadastro!$B$2:$D$38, 3, FALSE), "") | E5: =IFERROR(VLOOKUP(A5, Cadastro!$B$2:$E$38, 4, FALSE), "") | F5: =IFERROR(VLOOKUP(A5, Cadastro!$B$2:$J$38, 9, FALSE), "BRL") | G5: =IF(F5="USD", Indicadores!$E$2, IF(F5="GBP", Indicadores!$F$2, 1)) | H5: 12000 | I5: =H5*G5 | J5: 14160 | K5: =J5*G5 | L5: 650 | M5: =(K5-I5)+L5 | N5: =IF(I5>0, M5/I5, 0) | O5: =IF(#REF!>0, K5/#REF!, 0) | P5: 0.03 | Q5: =O5-P5 | R5: Poupança
A6: CLR-CSMG3 | B6: =IFERROR(VLOOKUP(A6, Cadastro!$B$2:$G$38, 5, FALSE), "") | C6: =IFERROR(VLOOKUP(A6, Cadastro!$B$2:$C$38, 2, FALSE), "") | D6: =IFERROR(VLOOKUP(A6, Cadastro!$B$2:$D$38, 3, FALSE), "") | E6: =IFERROR(VLOOKUP(A6, Cadastro!$B$2:$E$38, 4, FALSE), "") | F6: =IFERROR(VLOOKUP(A6, Cadastro!$B$2:$J$38, 9, FALSE), "BRL") | G6: =IF(F6="USD", Indicadores!$E$2, IF(F6="GBP", Indicadores!$F$2, 1)) | H6: 8000 | I6: =H6*G6 | J6: 8880 | K6: =J6*G6 | L6: 0 | M6: =(K6-I6)+L6 | N6: =IF(I6>0, M6/I6, 0) | O6: =IF(#REF!>0, K6/#REF!, 0) | P6: 0.03 | Q6: =O6-P6 | R6: Poupança
A7: CLR-POMO4 | B7: =IFERROR(VLOOKUP(A7, Cadastro!$B$2:$G$38, 5, FALSE), "") | C7: =IFERROR(VLOOKUP(A7, Cadastro!$B$2:$C$38, 2, FALSE), "") | D7: =IFERROR(VLOOKUP(A7, Cadastro!$B$2:$D$38, 3, FALSE), "") | E7: =IFERROR(VLOOKUP(A7, Cadastro!$B$2:$E$38, 4, FALSE), "") | F7: =IFERROR(VLOOKUP(A7, Cadastro!$B$2:$J$38, 9, FALSE), "BRL") | G7: =IF(F7="USD", Indicadores!$E$2, IF(F7="GBP", Indicadores!$F$2, 1)) | H7: 6000 | I7: =H7*G7 | J7: 6660 | K7: =J7*G7 | L7: 0 | M7: =(K7-I7)+L7 | N7: =IF(I7>0, M7/I7, 0) | O7: =IF(#REF!>0, K7/#REF!, 0) | P7: 0.03 | Q7: =O7-P7 | R7: Poupança
A8: CLR-ORVR3 | B8: =IFERROR(VLOOKUP(A8, Cadastro!$B$2:$G$38, 5, FALSE), "") | C8: =IFERROR(VLOOKUP(A8, Cadastro!$B$2:$C$38, 2, FALSE), "") | D8: =IFERROR(VLOOKUP(A8, Cadastro!$B$2:$D$38, 3, FALSE), "") | E8: =IFERROR(VLOOKUP(A8, Cadastro!$B$2:$E$38, 4, FALSE), "") | F8: =IFERROR(VLOOKUP(A8, Cadastro!$B$2:$J$38, 9, FALSE), "BRL") | G8: =IF(F8="USD", Indicadores!$E$2, IF(F8="GBP", Indicadores!$F$2, 1)) | H8: 7000 | I8: =H8*G8 | J8: 7770 | K8: =J8*G8 | L8: 0 | M8: =(K8-I8)+L8 | N8: =IF(I8>0, M8/I8, 0) | O8: =IF(#REF!>0, K8/#REF!, 0) | P8: 0.03 | Q8: =O8-P8 | R8: Poupança
A9: CLR-GOLD11 | B9: =IFERROR(VLOOKUP(A9, Cadastro!$B$2:$G$38, 5, FALSE), "") | C9: =IFERROR(VLOOKUP(A9, Cadastro!$B$2:$C$38, 2, FALSE), "") | D9: =IFERROR(VLOOKUP(A9, Cadastro!$B$2:$D$38, 3, FALSE), "") | E9: =IFERROR(VLOOKUP(A9, Cadastro!$B$2:$E$38, 4, FALSE), "") | F9: =IFERROR(VLOOKUP(A9, Cadastro!$B$2:$J$38, 9, FALSE), "BRL") | G9: =IF(F9="USD", Indicadores!$E$2, IF(F9="GBP", Indicadores!$F$2, 1)) | H9: 5000 | I9: =H9*G9 | J9: 5550 | K9: =J9*G9 | L9: 0 | M9: =(K9-I9)+L9 | N9: =IF(I9>0, M9/I9, 0) | O9: =IF(#REF!>0, K9/#REF!, 0) | P9: 0.03 | Q9: =O9-P9 | R9: Poupança
A10: XP-CDB0427 | B10: =IFERROR(VLOOKUP(A10, Cadastro!$B$2:$G$38, 5, FALSE), "") | C10: =IFERROR(VLOOKUP(A10, Cadastro!$B$2:$C$38, 2, FALSE), "") | D10: =IFERROR(VLOOKUP(A10, Cadastro!$B$2:$D$38, 3, FALSE), "") | E10: =IFERROR(VLOOKUP(A10, Cadastro!$B$2:$E$38, 4, FALSE), "") | F10: =IFERROR(VLOOKUP(A10, Cadastro!$B$2:$J$38, 9, FALSE), "BRL") | G10: =IF(F10="USD", Indicadores!$E$2, IF(F10="GBP", Indicadores!$F$2, 1)) | H10: 40000 | I10: =H10*G10 | J10: 45200 | K10: =J10*G10 | L10: 0 | M10: =(K10-I10)+L10 | N10: =IF(I10>0, M10/I10, 0) | O10: =IF(#REF!>0, K10/#REF!, 0) | P10: 0.03 | Q10: =O10-P10 | R10: Poupança
A11: XP-DEB2034 | B11: =IFERROR(VLOOKUP(A11, Cadastro!$B$2:$G$38, 5, FALSE), "") | C11: =IFERROR(VLOOKUP(A11, Cadastro!$B$2:$C$38, 2, FALSE), "") | D11: =IFERROR(VLOOKUP(A11, Cadastro!$B$2:$D$38, 3, FALSE), "") | E11: =IFERROR(VLOOKUP(A11, Cadastro!$B$2:$E$38, 4, FALSE), "") | F11: =IFERROR(VLOOKUP(A11, Cadastro!$B$2:$J$38, 9, FALSE), "BRL") | G11: =IF(F11="USD", Indicadores!$E$2, IF(F11="GBP", Indicadores!$F$2, 1)) | H11: 25000 | I11: =H11*G11 | J11: 27750 | K11: =J11*G11 | L11: 0 | M11: =(K11-I11)+L11 | N11: =IF(I11>0, M11/I11, 0) | O11: =IF(#REF!>0, K11/#REF!, 0) | P11: 0.03 | Q11: =O11-P11 | R11: Poupança
A12: XP-IPCA2032 | B12: =IFERROR(VLOOKUP(A12, Cadastro!$B$2:$G$38, 5, FALSE), "") | C12: =IFERROR(VLOOKUP(A12, Cadastro!$B$2:$C$38, 2, FALSE), "") | D12: =IFERROR(VLOOKUP(A12, Cadastro!$B$2:$D$38, 3, FALSE), "") | E12: =IFERROR(VLOOKUP(A12, Cadastro!$B$2:$E$38, 4, FALSE), "") | F12: =IFERROR(VLOOKUP(A12, Cadastro!$B$2:$J$38, 9, FALSE), "BRL") | G12: =IF(F12="USD", Indicadores!$E$2, IF(F12="GBP", Indicadores!$F$2, 1)) | H12: 15000 | I12: =H12*G12 | J12: 16650 | K12: =J12*G12 | L12: 0 | M12: =(K12-I12)+L12 | N12: =IF(I12>0, M12/I12, 0) | O12: =IF(#REF!>0, K12/#REF!, 0) | P12: 0.03 | Q12: =O12-P12 | R12: Poupança
A13: XP-IPCA2035 | B13: =IFERROR(VLOOKUP(A13, Cadastro!$B$2:$G$38, 5, FALSE), "") | C13: =IFERROR(VLOOKUP(A13, Cadastro!$B$2:$C$38, 2, FALSE), "") | D13: =IFERROR(VLOOKUP(A13, Cadastro!$B$2:$D$38, 3, FALSE), "") | E13: =IFERROR(VLOOKUP(A13, Cadastro!$B$2:$E$38, 4, FALSE), "") | F13: =IFERROR(VLOOKUP(A13, Cadastro!$B$2:$J$38, 9, FALSE), "BRL") | G13: =IF(F13="USD", Indicadores!$E$2, IF(F13="GBP", Indicadores!$F$2, 1)) | H13: 10000 | I13: =H13*G13 | J13: 11100 | K13: =J13*G13 | L13: 0 | M13: =(K13-I13)+L13 | N13: =IF(I13>0, M13/I13, 0) | O13: =IF(#REF!>0, K13/#REF!, 0) | P13: 0.03 | Q13: =O13-P13 | R13: Poupança
A14: XP-IPCA2026 | B14: =IFERROR(VLOOKUP(A14, Cadastro!$B$2:$G$38, 5, FALSE), "") | C14: =IFERROR(VLOOKUP(A14, Cadastro!$B$2:$C$38, 2, FALSE), "") | D14: =IFERROR(VLOOKUP(A14, Cadastro!$B$2:$D$38, 3, FALSE), "") | E14: =IFERROR(VLOOKUP(A14, Cadastro!$B$2:$E$38, 4, FALSE), "") | F14: =IFERROR(VLOOKUP(A14, Cadastro!$B$2:$J$38, 9, FALSE), "BRL") | G14: =IF(F14="USD", Indicadores!$E$2, IF(F14="GBP", Indicadores!$F$2, 1)) | H14: 5000 | I14: =H14*G14 | J14: 5550 | K14: =J14*G14 | L14: 0 | M14: =(K14-I14)+L14 | N14: =IF(I14>0, M14/I14, 0) | O14: =IF(#REF!>0, K14/#REF!, 0) | P14: 0.03 | Q14: =O14-P14 | R14: Poupança
A15: XP-VGHF11 | B15: =IFERROR(VLOOKUP(A15, Cadastro!$B$2:$G$38, 5, FALSE), "") | C15: =IFERROR(VLOOKUP(A15, Cadastro!$B$2:$C$38, 2, FALSE), "") | D15: =IFERROR(VLOOKUP(A15, Cadastro!$B$2:$D$38, 3, FALSE), "") | E15: =IFERROR(VLOOKUP(A15, Cadastro!$B$2:$E$38, 4, FALSE), "") | F15: =IFERROR(VLOOKUP(A15, Cadastro!$B$2:$J$38, 9, FALSE), "BRL") | G15: =IF(F15="USD", Indicadores!$E$2, IF(F15="GBP", Indicadores!$F$2, 1)) | H15: 10000 | I15: =H15*G15 | J15: 11100 | K15: =J15*G15 | L15: 150 | M15: =(K15-I15)+L15 | N15: =IF(I15>0, M15/I15, 0) | O15: =IF(#REF!>0, K15/#REF!, 0) | P15: 0.03 | Q15: =O15-P15 | R15: Poupança
... A39: XP-CDBCW | B39: =IFERROR(VLOOKUP(A39, Cadastro!$B$2:$G$38, 5, FALSE), "") | C39: =IFERROR(VLOOKUP(A39, Cadastro!$B$2:$C$38, 2, FALSE), "") | D39: =IFERROR(VLOOKUP(A39, Cadastro!$B$2:$D$38, 3, FALSE), "") | E39: =IFERROR(VLOOKUP(A39, Cadastro!$B$2:$E$38, 4, FALSE), "") | F39: =IFERROR(VLOOKUP(A39, Cadastro!$B$2:$J$38, 9, FALSE), "BRL") | G39: =IF(F39="USD", Indicadores!$E$2, IF(F39="GBP", Indicadores!$F$2, 1)) | H39: 20000 | I39: =H39*G39 | J39: 22200 | K39: =J39*G39 | L39: 0 | M39: =(K39-I39)+L39 | N39: =IF(I39>0, M39/I39, 0) | O39: =IF(#REF!>0, K39/#REF!, 0) | P39: 0.03 | Q39: =O39-P39 | R39: 300k
A40: TOTAL CONSOLIDADO | I40: =SUM(I4:I39) | K40: =SUM(K4:K39) | L40: =SUM(L4:L39) | M40: =SUM(M4:M39) | N40: =IF(#REF!>0,#REF! /#REF!, 0) | O40: =SUM(O4:O39) | P40: =SUM(P4:P39) | Q40: =#REF!-#REF!

Sheet Cadastro
A1: ID | B1: Código | C1: Instituição | D1: Classe | E1: Subclasse | F1: Ativo | G1: Ticker | H1: Valor Aplicado Inicial | I1: Data Entrada | J1: Moeda | K1: Ativo Ativo | L1: Observação
A2: 1 | B2: MP-CONTA | C2: Mercado Pago | D2: Caixa | E2: Conta Remunerada | F2: Conta Mercado Pago | G2: MP | H2: 1500 | I2: 45778 | J2: BRL | K2: Sim | L2: Carro
A3: 2 | B3: CLR-VALE3 | C3: Clear | D3: Renda Variável | E3: Ações | F3: Vale ON | G3: VALE3 | H3: 12000 | I3: 45778 | J3: BRL | K3: Sim | L3: Poupança
A4: 3 | B4: CLR-CSMG3 | C4: Clear | D4: Renda Variável | E4: Ações | F4: Copasa ON | G4: CSMG3 | H4: 8000 | I4: 45778 | J4: BRL | K4: Sim | L4: Poupança
A5: 4 | B5: CLR-POMO4 | C5: Clear | D5: Renda Variável | E5: Ações | F5: Marcopolo PN | G5: POMO4 | H5: 6000 | I5: 45778 | J5: BRL | K5: Sim | L5: Poupança
A6: 5 | B6: CLR-ORVR3 | C6: Clear | D6: Renda Variável | E6: Ações | F6: Orizon ON | G6: ORVR3 | H6: 7000 | I6: 45778 | J6: BRL | K6: Sim | L6: Poupança
A7: 6 | B7: CLR-GOLD11 | C7: Clear | D7: ETF | E7: Commodities | F7: Trend Ouro ETF | G7: GOLD11 | H7: 5000 | I7: 45778 | J7: BRL | K7: Sim | L7: Poupança
A8: 7 | B8: XP-CDB0427 | C8: XP | D8: Renda Fixa | E8: CDB | F8: Banco BBC - Grupo Simpar Abr/2027 | G8: CDB0427 | H8: 40000 | I8: 46183 | J8: BRL | K8: Sim | L8: Poupança
A9: 8 | B9: XP-DEB2034 | C9: XP | D9: Renda Fixa | E9: Debênture | F9: Petrobras Set/2034 | G9: PETR2034 | H9: 25000 | I9: 43747 | J9: BRL | K9: Sim | L9: Poupança
A10: 9 | B10: XP-IPCA2032 | C10: XP | D10: Tesouro Direto | E10: IPCA+ JS | F10: Tesouro IPCA+ 2032 JS | G10: NTNB2032 | H10: 15000 | I10: 45153 | J10: BRL | K10: Sim | L10: Poupança
A11: 10 | B11: XP-IPCA2035 | C11: XP | D11: Tesouro Direto | E11: IPCA+ | F11: Tesouro IPCA+ 2035 | G11: NTNB2035 | H11: 10000 | I11: 44347 | J11: BRL | K11: Sim | L11: Poupança
A12: 11 | B12: XP-IPCA2026 | C12: XP | D12: Tesouro Direto | E12: IPCA+ | F12: Tesouro IPCA+ 2026 | G12: NTNB2026 | H12: 5000 | I12: 44202 | J12: BRL | K12: Sim | L12: Poupança
A13: 12 | B13: XP-VGHF11 | C13: XP | D13: Renda Variável | E13: FII | F13: Valora Hedge Fund FII | G13: VGHF11 | H13: 10000 | I13: 45778 | J13: BRL | K13: Sim | L13: Poupança
... A37: 36 | B37: XP-CDBCW | C37: XP | D37: Renda Fixa | E37: CDB | F37: CDB CloudWalk InfinitePay 104%CDI | G37: CDBCW | H37: 20000 | I37: 46267 | J37: BRL | K37: Sim | L37: 300k

Sheet Indicadores
A1: Data Referência | B1: CDI (% a.a.) | C1: Selic (% a.a.) | D1: IPCA (%) | E1: Dólar (USD) | F1: Libra (GBP) | G1: Bitcoin (BTC) | H1: Observação
A2: 46225 | B2: 0.1415 | C2: 0.1425 | D2: 0.0016 | E2: 5.0566 | F2: 6.79 | G2: 335675 | H2: Taxas oficiais e cotações de referência | I2: 600000

Sheet Evolução Mensal
A1: Data | B1: Competência | C1: Instituição | D1: Classe | E1: Ativo | F1: Código | G1: Saldo Atual | H1: Aporte | I1: Resgate | J1: Dividendos/Juros | K1: Observação
A2: 45916 | B2: =DATE(YEAR(A2),MONTH(A2)+1,0) | C2: Avenue | D2: Exterior | E2: Disney | F2: AVE-DIS | G2: 1
A3: 45916 | B3: =DATE(YEAR(A3),MONTH(A3)+1,0) | C3: Avenue | D3: Exterior | E3: Google | F3: AVE-GOOGL | G3: 1
A4: 45916 | B4: =DATE(YEAR(A4),MONTH(A4)+1,0) | C4: Avenue | D4: Exterior | E4: Microsoft | F4: AVE-MSFT | G4: 1
A5: 45916 | B5: =DATE(YEAR(A5),MONTH(A5)+1,0) | C5: Avenue | D5: Exterior | E5: Shopify | F5: AVE-SHOP | G5: 1
A6: 45916 | B6: =DATE(YEAR(A6),MONTH(A6)+1,0) | C6: Avenue | D6: Exterior | E6: Blok | F6: AVE-BLOK | G6: 1
A7: 45916 | B7: =DATE(YEAR(A7),MONTH(A7)+1,0) | C7: Avenue | D7: Exterior | E7: IWM | F7: AVE-IWM | G7: 1
A8: 46220 | B8: =DATE(YEAR(A8),MONTH(A8)+1,0) | C8: C6 | D8: Renda Fixa | E8: CDB C6 Pós-Fixado Liq. Diária | F8: C6-CDB | G8: 1 | I8: 25000 | K8: transferido para Roberta
A9: 46225 | B9: =DATE(YEAR(A9),MONTH(A9)+1,0) | C9: Mercado Pago | D9: Caixa | E9: Caixa | F9: MP-CONTA | G9: 1
A10: 46225 | B10: =DATE(YEAR(A10),MONTH(A10)+1,0) | C10: Clear | D10: Ações | E10: Vale | F10: CLR-VALE3 | G10: 1
A11: 46225 | B11: =DATE(YEAR(A11),MONTH(A11)+1,0) | C11: Clear | D11: Ações | E11: Copasa ON | F11: CLR-CSMG3 | G11: 1
A12: 46225 | B12: =DATE(YEAR(A12),MONTH(A12)+1,0) | C12: Clear | D12: Ações | E12: Marcopolo SA | F12: CLR-POMO4 | G12: 1
A13: 46225 | B13: =DATE(YEAR(A13),MONTH(A13)+1,0) | C13: Clear | D13: Ações | E13: Orizon Valorizacao de Residuos SA | F13: CLR-ORVR3 | G13: 1
A14: 46225 | B14: =DATE(YEAR(A14),MONTH(A14)+1,0) | C14: Clear | D14: Fundo | E14: Trend ETF LBMA Gold Fundo de Índice | F14: CLR-GOLD11 | G14: 1
A15: 46225 | B15: =DATE(YEAR(A15),MONTH(A15)+1,0) | C15: XP | D15: Renda Fixa | E15: CDB BANCO BBC | F15: XP-CDB0427 | G15: 1
A16: 46225 | B16: =DATE(YEAR(A16),MONTH(A16)+1,0) | C16: XP | D16: Renda Fixa | E16: DEB PETROBRAS - SET/2034 | F16: XP-DEB2034 | G16: 1
A17: 46225 | B17: =DATE(YEAR(A17),MONTH(A17)+1,0) | C17: XP | D17: Tesouro Direto | E17: NTN-B ago/2032 | F17: XP-IPCA2032 | G17: 1
A18: 46225 | B18: =DATE(YEAR(A18),MONTH(A18)+1,0) | C18: XP | D18: Tesouro Direto | E18: NTNB PRINC mai/2035 | F18: XP-IPCA2035 | G18: 1
A19: 46225 | B19: =DATE(YEAR(A19),MONTH(A19)+1,0) | C19: XP | D19: Tesouro Direto | E19: NTNB PRINC ago/2026 | F19: XP-IPCA2026 | G19: 1 | I19: 2469.56
A20: 46225 | B20: =DATE(YEAR(A20),MONTH(A20)+1,0) | C20: XP | D20: Fundo Imobiliário | E20: VALORA HEDGE FUND | F20: XP-VGHF11 | G20: 1
A21: 46225 | B21: =DATE(YEAR(A21),MONTH(A21)+1,0) | C21: XP | D21: Fundo Imobiliário | E21: RBR Crédito Imobiliário Estruturado | F21: XP-RBRY11 | G21: 1
A22: 46225 | B22: =DATE(YEAR(A22),MONTH(A22)+1,0) | C22: XP | D22: Fundo Imobiliário | E22: Mérito Desenvolvimento Imobiliário | F22: XP-MFII11 | G22: 1
A23: 46225 | B23: =DATE(YEAR(A23),MONTH(A23)+1,0) | C23: Binance | D23: Cripto | E23: Bitcoin | F23: BIN-BTC | G23: 1
A24: 46225 | B24: =DATE(YEAR(A24),MONTH(A24)+1,0) | C24: Binance | D24: Cripto | E24: Sui | F24: BIN-SUI | G24: 1
A25: 46225 | B25: =DATE(YEAR(A25),MONTH(A25)+1,0) | C25: Binance | D25: Cripto | E25: avax | F25: BIN-AVAX | G25: 1
A26: 46225 | B26: =DATE(YEAR(A26),MONTH(A26)+1,0) | C26: Binance | D26: Cripto | E26: Etherium | F26: BIN-ETH | G26: 1
A27: 46225 | B27: =DATE(YEAR(A27),MONTH(A27)+1,0) | C27: Binance | D27: Cripto | E27: Solana | F27: BIN-SOL | G27: 1
A28: 46225 | B28: =DATE(YEAR(A28),MONTH(A28)+1,0) | C28: Avenue | D28: Exterior | E28: Disney | F28: AVE-DIS | G28: 1
A29: 46225 | B29: =DATE(YEAR(A29),MONTH(A29)+1,0) | C29: Avenue | D29: Exterior | E29: Google | F29: AVE-GOOGL | G29: 1
A30: 46225 | B30: =DATE(YEAR(A30),MONTH(A30)+1,0) | C30: Avenue | D30: Exterior | E30: Microsoft | F30: AVE-MSFT | G30: 1
A31: 46225 | B31: =DATE(YEAR(A31),MONTH(A31)+1,0) | C31: Avenue | D31: Exterior | E31: Shopify | F31: AVE-SHOP | G31: 1
... A37: 46226 | B37: =DATE(YEAR(A37),MONTH(A37)+1,0) | C37: C6 | D37: Renda Fixa | E37: CDI C6 | F37: C6-CDI | G37: 1
A38: 46264 | B38: =DATE(YEAR(A38),MONTH(A38)+1,0) | C38: Mercado Pago | D38: Caixa | E38: Caixa | F38: MP-CONTA | G38: 1 | H38: 2000
A39: 46264 | B39: =DATE(YEAR(A39),MONTH(A39)+1,0) | C39: Clear | D39: Ações | E39: Vale | F39: CLR-VALE3 | G39: 1
A40: 46264 | B40: =DATE(YEAR(A40),MONTH(A40)+1,0) | C40: Clear | D40: Ações | E40: Copasa ON | F40: CLR-CSMG3 | G40: 1
A41: 46264 | B41: =DATE(YEAR(A41),MONTH(A41)+1,0) | C41: Clear | D41: Ações | E41: Marcopolo SA | F41: CLR-POMO4 | G41: 1
A42: 46264 | B42: =DATE(YEAR(A42),MONTH(A42)+1,0) | C42: Clear | D42: Ações | E42: Orizon Valorizacao de Residuos SA | F42: CLR-ORVR3 | G42: 1
A43: 46264 | B43: =DATE(YEAR(A43),MONTH(A43)+1,0) | C43: Clear | D43: Fundo | E43: Trend ETF LBMA Gold Fundo de Índice | F43: CLR-GOLD11 | G43: 1
A44: 46264 | B44: =DATE(YEAR(A44),MONTH(A44)+1,0) | C44: XP | D44: Renda Fixa | E44: CDB BANCO BBC | F44: XP-CDB0427 | G44: 1
A45: 46264 | B45: =DATE(YEAR(A45),MONTH(A45)+1,0) | C45: XP | D45: Renda Fixa | E45: DEB PETROBRAS - SET/2034 | F45: XP-DEB2034 | G45: 1
...

Sheet Movimentações
